<robot name="diff_robot">
  <link name="base_link">
    <inertial>
      <mass value="25.0"/>
      <inertia ixx="0.6041666666666666" iyy="1.1041666666666663" izz="1.5416666666666665" ixz="0" ixy="0" iyz="0"/>
      <origin xyz="0.0 0.0 0.05"/>
    </inertial>
    <visual>
      <geometry>
        <box size="0.7 0.5 0.2"/>
      </geometry>
      <origin xyz="0.0 0.0 0.05"/>
      <material name="body_color">
        <color rgba="0.0 0.0 1.0 1.0"/>
      </material>
    </visual>
    <collision>
      <geometry>
        <box size="0.7 0.5 0.2"/>
      </geometry>
      <origin xyz="0.0 0.0 0.05"/>
    </collision>
  </link>
  <link name="wheel_fr">
    <inertial>
      <mass value="2.0"/>
      <inertia ixx="0.011666666666666667" iyy="0.011666666666666667" izz="0.010000000000000002" ixz="0" ixy="0" iyz="0"/>
      <origin xyz="0.0 0.0 0.05"/>
    </inertial>
    <visual>
      <geometry>
        <cylinder length="0.1" radius="0.2"/>
      </geometry>
      <origin xyz="0.0 0.0 0.05"/>
      <material name="wheel_color">
        <color rgba="0.0 0.0 0.0 1.0"/>
      </material>
    </visual>
    <collision>
      <geometry>
        <cylinder length="0.1" radius="0.2"/>
      </geometry>
      <origin xyz="0.0 0.0 0.05"/>
    </collision>
  </link>
  <link name="wheel_fl">
    <inertial>
      <mass value="2.0"/>
      <inertia ixx="0.011666666666666667" iyy="0.011666666666666667" izz="0.010000000000000002" ixz="0" ixy="0" iyz="0"/>
      <origin xyz="0.0 0.0 0.05"/>
    </inertial>
    <visual>
      <geometry>
        <cylinder length="0.1" radius="0.2"/>
      </geometry>
      <origin xyz="0.0 0.0 0.05"/>
      <material name="wheel_color">
        <color rgba="0.0 0.0 0.0 1.0"/>
      </material>
    </visual>
    <collision>
      <geometry>
        <cylinder length="0.1" radius="0.2"/>
      </geometry>
      <origin xyz="0.0 0.0 0.05"/>
    </collision>
  </link>
  <link name="wheel_rr">
    <inertial>
      <mass value="2.0"/>
      <inertia ixx="0.011666666666666667" iyy="0.011666666666666667" izz="0.010000000000000002" ixz="0" ixy="0" iyz="0"/>
      <origin xyz="0.0 0.0 0.05"/>
    </inertial>
    <visual>
      <geometry>
        <cylinder length="0.1" radius="0.2"/>
      </geometry>
      <origin xyz="0.0 0.0 0.05"/>
      <material name="wheel_color">
        <color rgba="0.0 0.0 0.0 1.0"/>
      </material>
    </visual>
    <collision>
      <geometry>
        <cylinder length="0.1" radius="0.2"/>
      </geometry>
      <origin xyz="0.0 0.0 0.05"/>
    </collision>
  </link>
  <link name="wheel_rl">
    <inertial>
      <mass value="2.0"/>
      <inertia ixx="0.011666666666666667" iyy="0.011666666666666667" izz="0.010000000000000002" ixz="0" ixy="0" iyz="0"/>
      <origin xyz="0.0 0.0 0.05"/>
    </inertial>
    <visual>
      <geometry>
        <cylinder length="0.1" radius="0.2"/>
      </geometry>
      <origin xyz="0.0 0.0 0.05"/>
      <material name="wheel_color">
        <color rgba="0.0 0.0 0.0 1.0"/>
      </material>
    </visual>
    <collision>
      <geometry>
        <cylinder length="0.1" radius="0.2"/>
      </geometry>
      <origin xyz="0.0 0.0 0.05"/>
    </collision>
  </link>
  <link name="camera_link">
    <inertial>
      <mass value="0.5"/>
      <inertia ixx="0.0020833333333333337" iyy="0.0005208333333333334" izz="0.0017708333333333337" ixz="0" ixy="0" iyz="0"/>
      <origin xyz="0.0 0.0 0.05"/>
    </inertial>
    <visual>
      <geometry>
        <box size="0.05 0.2 0.1"/>
      </geometry>
      <origin xyz="0.0 0.0 0.05"/>
      <material name="camera_color">
        <color rgba="0.86 0.86 0.86 1.0"/>
      </material>
    </visual>
    <collision>
      <geometry>
        <box size="0.05 0.2 0.1"/>
      </geometry>
      <origin xyz="0.0 0.0 0.05"/>
    </collision>
  </link>
  <joint type="fixed" name="camera_joint">
    <parent link="base_link"/>
    <child link="camera_link"/>
    <origin xyz="0.35 0.0 0.15" rpy="0.0 0.0 0.0"/>
    <axis xyz="0.0 0.0 1.0"/>
  </joint>
  <joint type="continuous" name="joint_fr">
    <parent link="base_link"/>
    <child link="wheel_fr"/>
    <origin xyz="0.25 0.25 0.05" rpy="-1.5707963267948966 0.0 0.0"/>
    <axis xyz="0.0 0.0 1.0"/>
  </joint>
  <joint type="continuous" name="joint_fl">
    <parent link="base_link"/>
    <child link="wheel_fl"/>
    <origin xyz="0.25 -0.25 0.05" rpy="1.5707963267948966 0.0 0.0"/>
    <axis xyz="0.0 0.0 -1.0"/>
  </joint>
  <joint type="continuous" name="joint_rr">
    <parent link="base_link"/>
    <child link="wheel_rr"/>
    <origin xyz="-0.25 0.25 0.05" rpy="-1.5707963267948966 0.0 0.0"/>
    <axis xyz="0.0 0.0 1.0"/>
  </joint>
  <joint type="continuous" name="joint_rl">
    <parent link="base_link"/>
    <child link="wheel_rl"/>
    <origin xyz="-0.25 -0.25 0.05" rpy="1.5707963267948966 0.0 0.0"/>
    <axis xyz="0.0 0.0 -1.0"/>
  </joint>
  <gazebo>
    <plugin name="gz_ros2_control::GazeboSimROS2ControlPlugin" filename="gz_ros2_control-system">
      <parameters>diff_control.yaml</parameters>
    </plugin>
  </gazebo>
  <ros2_control name="gazebo_sim_system" type="system">
    <hardware>
      <plugin>gz_ros2_control/GazeboSimSystem</plugin>
    </hardware>
    <joint name="joint_fr">
      <command_interface name="velocity"/>
      <state_interface name="position"/>
      <state_interface name="velocity"/>
    </joint>
    <joint name="joint_fl">
      <command_interface name="velocity"/>
      <state_interface name="position"/>
      <state_interface name="velocity"/>
    </joint>
    <joint name="joint_rr">
      <command_interface name="velocity"/>
      <state_interface name="position"/>
      <state_interface name="velocity"/>
    </joint>
    <joint name="joint_rl">
      <command_interface name="velocity"/>
      <state_interface name="position"/>
      <state_interface name="velocity"/>
    </joint>
  </ros2_control>
  <gazebo>
    <plugin filename="gz-sim-sensors-system" name="gz::sim::systems::Sensors">
      <render_engine>ogre</render_engine>
    </plugin>
  </gazebo>
  <gazebo reference="camera_link">
    <sensor name="camera" type="camera">
      <camera>
        <horizontal_fov>1.0471975511965976</horizontal_fov>
        <image>
          <width>640</width>
          <height>480</height>
        </image>
        <clip>
          <near>0.1</near>
          <far>100.0</far>
        </clip>
      </camera>
      <update_rate>30.0</update_rate>
      <always_on>1</always_on>
      <visualize>true</visualize>
      <topic>diff_robot/camera</topic>
      <topic>diff_robot/camera_info</topic>
    </sensor>
  </gazebo>
</robot>
